Workbook

Sheet RunTime1
A1: Dataset | B1: Chromosome | C1: Sample | D1: Variants | E1: Ploidy | F1: vcflib | G1: cpu_t1_time | H1: cpu_t2_time | I1: gpu_t1_time | J1: gpu_t2_time | K1: speedup_cpu_t2_vs_t1 | L1: speedup_cpu_t1_vs_vcflib | M1: speedup_cpu_t2_vs_vcflib | N1: speedup_gpu_t2_vs_t1 | O1: speedup_gpu_t2_vs_vcflib | P1: speedup_gpu_t1_vs_vcflib | Q1: speedup_gpu_t2_vs_cpu_t2 | R1: speedup_gpu_t1_vs_cpu_t1 | S1: speedup_gpu_t1_vs_cpu_t2 | T1: speedup_gpu_t2_vs_cpu_t1 | U1: Notes
A2: Platinum | B2: chr1 | C2: NA12877 | D2: 319247 | E2: 2 | F2: 25m 8s 37ms | G2: 4s 743ms | H2: 7s 2ms | I2: 6s 673ms | J2: 5s 949ms | K2: .67x | L2: 317.94x | M2: 215.36x | N2: 1.12x | O2: =AVERAGE(ParseTime(RunTime1!F2),ParseTime(RunTime2!F2),ParseTime(RunTime3!F2),ParseTime(RunTime4!F2)) / AVERAGE(ParseTime(RunTime1!J2),ParseTime(RunTime2!J2),ParseTime(RunTime3!J2),ParseTime(RunTime4!J2)) -> 140.80047 | P2: =AVERAGE(ParseTime(RunTime1!F2),ParseTime(RunTime2!F2),ParseTime(RunTime3!F2),ParseTime(RunTime4!F2)) / AVERAGE(ParseTime(RunTime1!I2),ParseTime(RunTime2!I2),ParseTime(RunTime3!I2),ParseTime(RunTime4!I2)) -> 150.16231 | Q2: =AVERAGE(ParseTime(RunTime1!H2),ParseTime(RunTime2!H2),ParseTime(RunTime3!H2),ParseTime(RunTime4!H2)) / AVERAGE(ParseTime(RunTime1!J2),ParseTime(RunTime2!J2),ParseTime(RunTime3!J2),ParseTime(RunTime4!J2)) -> 1.0387539 | R2: =AVERAGE(ParseTime(RunTime1!G2),ParseTime(RunTime2!G2),ParseTime(RunTime3!G2),ParseTime(RunTime4!G2)) / AVERAGE(ParseTime(RunTime1!I2),ParseTime(RunTime2!I2),ParseTime(RunTime3!I2),ParseTime(RunTime4!I2)) -> 1.0428153 | S2: =AVERAGE(ParseTime(RunTime1!H2),ParseTime(RunTime2!H2),ParseTime(RunTime3!H2),ParseTime(RunTime4!H2)) / AVERAGE(ParseTime(RunTime1!I2),ParseTime(RunTime2!I2),ParseTime(RunTime3!I2),ParseTime(RunTime4!I2)) -> 1.1078207 | T2: =AVERAGE(ParseTime(RunTime1!G2),ParseTime(RunTime2!G2),ParseTime(RunTime3!G2),ParseTime(RunTime4!G2)) / AVERAGE(ParseTime(RunTime1!J2),ParseTime(RunTime2!J2),ParseTime(RunTime3!J2),ParseTime(RunTime4!J2)) -> 0.97780119 | U2: vcf2fasta-rust Validation Passed; vcflib Validation Passed
A3: Platinum | B3: chr1 | C3: NA12878 | D3: 316061 | E3: 2 | F3: 13m 53s 523ms | G3: 8s 489ms | H3: 4s 282ms | I3: 5s 256ms | J3: 7s 340ms | K3: 1.98x | L3: 98.18x | M3: 194.66x | N3: .71x | O3: =AVERAGE(ParseTime(RunTime1!F3),ParseTime(RunTime2!F3),ParseTime(RunTime3!F3),ParseTime(RunTime4!F3)) / AVERAGE(ParseTime(RunTime1!J3),ParseTime(RunTime2!J3),ParseTime(RunTime3!J3),ParseTime(RunTime4!J3)) -> 121.73841 | P3: =AVERAGE(ParseTime(RunTime1!F3),ParseTime(RunTime2!F3),ParseTime(RunTime3!F3),ParseTime(RunTime4!F3)) / AVERAGE(ParseTime(RunTime1!I3),ParseTime(RunTime2!I3),ParseTime(RunTime3!I3),ParseTime(RunTime4!I3)) -> 131.53884 | Q3: =AVERAGE(ParseTime(RunTime1!H3),ParseTime(RunTime2!H3),ParseTime(RunTime3!H3),ParseTime(RunTime4!H3)) / AVERAGE(ParseTime(RunTime1!J3),ParseTime(RunTime2!J3),ParseTime(RunTime3!J3),ParseTime(RunTime4!J3)) -> 0.94838583 | R3: =AVERAGE(ParseTime(RunTime1!G3),ParseTime(RunTime2!G3),ParseTime(RunTime3!G3),ParseTime(RunTime4!G3)) / AVERAGE(ParseTime(RunTime1!I3),ParseTime(RunTime2!I3),ParseTime(RunTime3!I3),ParseTime(RunTime4!I3)) -> 1.1331022 | S3: =AVERAGE(ParseTime(RunTime1!H3),ParseTime(RunTime2!H3),ParseTime(RunTime3!H3),ParseTime(RunTime4!H3)) / AVERAGE(ParseTime(RunTime1!I3),ParseTime(RunTime2!I3),ParseTime(RunTime3!I3),ParseTime(RunTime4!I3)) -> 1.0247347 | T3: =AVERAGE(ParseTime(RunTime1!G3),ParseTime(RunTime2!G3),ParseTime(RunTime3!G3),ParseTime(RunTime4!G3)) / AVERAGE(ParseTime(RunTime1!J3),ParseTime(RunTime2!J3),ParseTime(RunTime3!J3),ParseTime(RunTime4!J3)) -> 1.0486793 | U3: vcf2fasta-rust Validation Passed; vcflib Validation Passed
A4: Platinum | B4: chr2 | C4: NA12877 | D4: 328730 | E4: 2 | F4: 14s 172ms | G4: 5s 130ms | H4: 5s 16ms | I4: 5s 207ms | J4: 5s 738ms | K4: 1.02x | L4: 2.76x | M4: 2.82x | N4: .90x | O4: =AVERAGE(ParseTime(RunTime1!F4),ParseTime(RunTime2!F4),ParseTime(RunTime3!F4),ParseTime(RunTime4!F4)) / AVERAGE(ParseTime(RunTime1!J4),ParseTime(RunTime2!J4),ParseTime(RunTime3!J4),ParseTime(RunTime4!J4)) -> 2.2017179 | P4: =AVERAGE(ParseTime(RunTime1!F4),ParseTime(RunTime2!F4),ParseTime(RunTime3!F4),ParseTime(RunTime4!F4)) / AVERAGE(ParseTime(RunTime1!I4),ParseTime(RunTime2!I4),ParseTime(RunTime3!I4),ParseTime(RunTime4!I4)) -> 2.4598652 | Q4: =AVERAGE(ParseTime(RunTime1!H4),ParseTime(RunTime2!H4),ParseTime(RunTime3!H4),ParseTime(RunTime4!H4)) / AVERAGE(ParseTime(RunTime1!J4),ParseTime(RunTime2!J4),ParseTime(RunTime3!J4),ParseTime(RunTime4!J4)) -> 0.75697652 | R4: =AVERAGE(ParseTime(RunTime1!G4),ParseTime(RunTime2!G4),ParseTime(RunTime3!G4),ParseTime(RunTime4!G4)) / AVERAGE(ParseTime(RunTime1!I4),ParseTime(RunTime2!I4),ParseTime(RunTime3!I4),ParseTime(RunTime4!I4)) -> 1.1201058 | S4: =AVERAGE(ParseTime(RunTime1!H4),ParseTime(RunTime2!H4),ParseTime(RunTime3!H4),ParseTime(RunTime4!H4)) / AVERAGE(ParseTime(RunTime1!I4),ParseTime(RunTime2!I4),ParseTime(RunTime3!I4),ParseTime(RunTime4!I4)) -> 0.84573062 | T4: =AVERAGE(ParseTime(RunTime1!G4),ParseTime(RunTime2!G4),ParseTime(RunTime3!G4),ParseTime(RunTime4!G4)) / AVERAGE(ParseTime(RunTime1!J4),ParseTime(RunTime2!J4),ParseTime(RunTime3!J4),ParseTime(RunTime4!J4)) -> 1.0025577 | U4: vcf2fasta-rust Validation Passed; vcflib Validation Passed
A5: Platinum | B5: chr2 | C5: NA12878 | D5: 335402 | E5: 2 | F5: N/A | G5: 5s 379ms | H5: 5s 794ms | I5: 6s 84ms | J5: 5s 708ms | K5: .92x | L5: N/A | M5: N/A | N5: 1.06x | O5: N/A | P5: N/A | Q5: =AVERAGE(ParseTime(RunTime1!H5),ParseTime(RunTime2!H5),ParseTime(RunTime3!H5),ParseTime(RunTime4!H5)) / AVERAGE(ParseTime(RunTime1!J5),ParseTime(RunTime2!J5),ParseTime(RunTime3!J5),ParseTime(RunTime4!J5)) -> 1.1001145 | R5: =AVERAGE(ParseTime(RunTime1!G5),ParseTime(RunTime2!G5),ParseTime(RunTime3!G5),ParseTime(RunTime4!G5)) / AVERAGE(ParseTime(RunTime1!I5),ParseTime(RunTime2!I5),ParseTime(RunTime3!I5),ParseTime(RunTime4!I5)) -> 0.79399302 | S5: =AVERAGE(ParseTime(RunTime1!H5),ParseTime(RunTime2!H5),ParseTime(RunTime3!H5),ParseTime(RunTime4!H5)) / AVERAGE(ParseTime(RunTime1!I5),ParseTime(RunTime2!I5),ParseTime(RunTime3!I5),ParseTime(RunTime4!I5)) -> 1.0375955 | T5: =AVERAGE(ParseTime(RunTime1!G5),ParseTime(RunTime2!G5),ParseTime(RunTime3!G5),ParseTime(RunTime4!G5)) / AVERAGE(ParseTime(RunTime1!J5),ParseTime(RunTime2!J5),ParseTime(RunTime3!J5),ParseTime(RunTime4!J5)) -> 0.84183404 | U5: vcf2fasta-rust Validation Passed (SKIPPED chr2:118112315 REF=AAAAT ALT=A GT=0|1 reason=overlap); vcflib Validation Failed (due to overlap)
A6: Platinum | B6: chr3 | C6: NA12877 | D6: 284815 | E6: 2 | F6: 9s 569ms | G6: 4s 423ms | H6: 10s 485ms | I6: 4s 262ms | J6: 6s 594ms | K6: .42x | L6: 2.16x | M6: .91x | N6: .64x | O6: =AVERAGE(ParseTime(RunTime1!F6),ParseTime(RunTime2!F6),ParseTime(RunTime3!F6),ParseTime(RunTime4!F6)) / AVERAGE(ParseTime(RunTime1!J6),ParseTime(RunTime2!J6),ParseTime(RunTime3!J6),ParseTime(RunTime4!J6)) -> 1.4791844 | P6: =AVERAGE(ParseTime(RunTime1!F6),ParseTime(RunTime2!F6),ParseTime(RunTime3!F6),ParseTime(RunTime4!F6)) / AVERAGE(ParseTime(RunTime1!I6),ParseTime(RunTime2!I6),ParseTime(RunTime3!I6),ParseTime(RunTime4!I6)) -> 1.8409366 | Q6: =AVERAGE(ParseTime(RunTime1!H6),ParseTime(RunTime2!H6),ParseTime(RunTime3!H6),ParseTime(RunTime4!H6)) / AVERAGE(ParseTime(RunTime1!J6),ParseTime(RunTime2!J6),ParseTime(RunTime3!J6),ParseTime(RunTime4!J6)) -> 0.99510458 | R6: =AVERAGE(ParseTime(RunTime1!G6),ParseTime(RunTime2!G6),ParseTime(RunTime3!G6),ParseTime(RunTime4!G6)) / AVERAGE(ParseTime(RunTime1!I6),ParseTime(RunTime2!I6),ParseTime(RunTime3!I6),ParseTime(RunTime4!I6)) -> 0.92628399 | S6: =AVERAGE(ParseTime(RunTime1!H6),ParseTime(RunTime2!H6),ParseTime(RunTime3!H6),ParseTime(RunTime4!H6)) / AVERAGE(ParseTime(RunTime1!I6),ParseTime(RunTime2!I6),ParseTime(RunTime3!I6),ParseTime(RunTime4!I6)) -> 1.2384693 | T6: =AVERAGE(ParseTime(RunTime1!G6),ParseTime(RunTime2!G6),ParseTime(RunTime3!G6),ParseTime(RunTime4!G6)) / AVERAGE(ParseTime(RunTime1!J6),ParseTime(RunTime2!J6),ParseTime(RunTime3!J6),ParseTime(RunTime4!J6)) -> 0.74426508 | U6: vcf2fasta-rust Validation Passed; vcflib Validation Passed
A7: Platinum | B7: chr3 | C7: NA12878 | D7: 280114 | E7: 2 | F7: 10s 342ms | G7: 4s 217ms | H7: 3s 449ms | I7: 5s 607ms | J7: 4s 772ms | K7: 1.22x | L7: 2.45x | M7: 2.99x | N7: 1.17x | O7: =AVERAGE(ParseTime(RunTime1!F7),ParseTime(RunTime2!F7),ParseTime(RunTime3!F7),ParseTime(RunTime4!F7)) / AVERAGE(ParseTime(RunTime1!J7),ParseTime(RunTime2!J7),ParseTime(RunTime3!J7),ParseTime(RunTime4!J7)) -> 0.58038042 | P7: =AVERAGE(ParseTime(RunTime1!F7),ParseTime(RunTime2!F7),ParseTime(RunTime3!F7),ParseTime(RunTime4!F7)) / AVERAGE(ParseTime(RunTime1!I7),ParseTime(RunTime2!I7),ParseTime(RunTime3!I7),ParseTime(RunTime4!I7)) -> 1.9006989 | Q7: =AVERAGE(ParseTime(RunTime1!H7),ParseTime(RunTime2!H7),ParseTime(RunTime3!H7),ParseTime(RunTime4!H7)) / AVERAGE(ParseTime(RunTime1!J7),ParseTime(RunTime2!J7),ParseTime(RunTime3!J7),ParseTime(RunTime4!J7)) -> 0.29147211 | R7: =AVERAGE(ParseTime(RunTime1!G7),ParseTime(RunTime2!G7),ParseTime(RunTime3!G7),ParseTime(RunTime4!G7)) / AVERAGE(ParseTime(RunTime1!I7),ParseTime(RunTime2!I7),ParseTime(RunTime3!I7),ParseTime(RunTime4!I7)) -> 0.74797129 | S7: =AVERAGE(ParseTime(RunTime1!H7),ParseTime(RunTime2!H7),ParseTime(RunTime3!H7),ParseTime(RunTime4!H7)) / AVERAGE(ParseTime(RunTime1!I7),ParseTime(RunTime2!I7),ParseTime(RunTime3!I7),ParseTime(RunTime4!I7)) -> 0.95454759 | T7: =AVERAGE(ParseTime(RunTime1!G7),ParseTime(RunTime2!G7),ParseTime(RunTime3!G7),ParseTime(RunTime4!G7)) / AVERAGE(ParseTime(RunTime1!J7),ParseTime(RunTime2!J7),ParseTime(RunTime3!J7),ParseTime(RunTime4!J7)) -> 0.22839382 | U7: vcf2fasta-rust Validation Passed; vcflib Validation Passed
A8: Platinum | B8: chr4 | C8: NA12877 | D8: 306846 | E8: 2 | F8: 11s 731ms | G8: 5s 255ms | H8: 3s 708ms | I8: 4s 230ms | J8: 6s 232ms | K8: 1.41x | L8: 2.23x | M8: 3.16x | N8: .67x | O8: =AVERAGE(ParseTime(RunTime1!F8),ParseTime(RunTime2!F8),ParseTime(RunTime3!F8),ParseTime(RunTime4!F8)) / AVERAGE(ParseTime(RunTime1!J8),ParseTime(RunTime2!J8),ParseTime(RunTime3!J8),ParseTime(RunTime4!J8)) -> 1.7187418 | P8: =AVERAGE(ParseTime(RunTime1!F8),ParseTime(RunTime2!F8),ParseTime(RunTime3!F8),ParseTime(RunTime4!F8)) / AVERAGE(ParseTime(RunTime1!I8),ParseTime(RunTime2!I8),ParseTime(RunTime3!I8),ParseTime(RunTime4!I8)) -> 2.0019445 | Q8: =AVERAGE(ParseTime(RunTime1!H8),ParseTime(RunTime2!H8),ParseTime(RunTime3!H8),ParseTime(RunTime4!H8)) / AVERAGE(ParseTime(RunTime1!J8),ParseTime(RunTime2!J8),ParseTime(RunTime3!J8),ParseTime(RunTime4!J8)) -> 0.73508479 | R8: =AVERAGE(ParseTime(RunTime1!G8),ParseTime(RunTime2!G8),ParseTime(RunTime3!G8),ParseTime(RunTime4!G8)) / AVERAGE(ParseTime(RunTime1!I8),ParseTime(RunTime2!I8),ParseTime(RunTime3!I8),ParseTime(RunTime4!I8)) -> 0.92887115 | S8: =AVERAGE(ParseTime(RunTime1!H8),ParseTime(RunTime2!H8),ParseTime(RunTime3!H8),ParseTime(RunTime4!H8)) / AVERAGE(ParseTime(RunTime1!I8),ParseTime(RunTime2!I8),ParseTime(RunTime3!I8),ParseTime(RunTime4!I8)) -> 0.85620714 | T8: =AVERAGE(ParseTime(RunTime1!G8),ParseTime(RunTime2!G8),ParseTime(RunTime3!G8),ParseTime(RunTime4!G8)) / AVERAGE(ParseTime(RunTime1!J8),ParseTime(RunTime2!J8),ParseTime(RunTime3!J8),ParseTime(RunTime4!J8)) -> 0.79746947 | U8: vcf2fasta-rust Validation Passed; vcflib Validation Passed
A9: Platinum | B9: chr4 | C9: NA12878 | D9: 301639 | E9: 2 | F9: 12s 991ms | G9: 3s 211ms | H9: 6s 916ms | I9: 5s 412ms | J9: 5s 238ms | K9: .46x | L9: 4.04x | M9: 1.87x | N9: 1.03x | O9: =AVERAGE(ParseTime(RunTime1!F9),ParseTime(RunTime2!F9),ParseTime(RunTime3!F9),ParseTime(RunTime4!F9)) / AVERAGE(ParseTime(RunTime1!J9),ParseTime(RunTime2!J9),ParseTime(RunTime3!J9),ParseTime(RunTime4!J9)) -> 1.4177522 | P9: =AVERAGE(ParseTime(RunTime1!F9),ParseTime(RunTime2!F9),ParseTime(RunTime3!F9),ParseTime(RunTime4!F9)) / AVERAGE(ParseTime(RunTime1!I9),ParseTime(RunTime2!I9),ParseTime(RunTime3!I9),ParseTime(RunTime4!I9)) -> 1.9071076 | Q9: =AVERAGE(ParseTime(RunTime1!H9),ParseTime(RunTime2!H9),ParseTime(RunTime3!H9),ParseTime(RunTime4!H9)) / AVERAGE(ParseTime(RunTime1!J9),ParseTime(RunTime2!J9),ParseTime(RunTime3!J9),ParseTime(RunTime4!J9)) -> 0.71654497 | R9: =AVERAGE(ParseTime(RunTime1!G9),ParseTime(RunTime2!G9),ParseTime(RunTime3!G9),ParseTime(RunTime4!G9)) / AVERAGE(ParseTime(RunTime1!I9),ParseTime(RunTime2!I9),ParseTime(RunTime3!I9),ParseTime(RunTime4!I9)) -> 0.75918065 | S9: =AVERAGE(ParseTime(RunTime1!H9),ParseTime(RunTime2!H9),ParseTime(RunTime3!H9),ParseTime(RunTime4!H9)) / AVERAGE(ParseTime(RunTime1!I9),ParseTime(RunTime2!I9),ParseTime(RunTime3!I9),ParseTime(RunTime4!I9)) -> 0.96386969 | T9: =AVERAGE(ParseTime(RunTime1!G9),ParseTime(RunTime2!G9),ParseTime(RunTime3!G9),ParseTime(RunTime4!G9)) / AVERAGE(ParseTime(RunTime1!J9),ParseTime(RunTime2!J9),ParseTime(RunTime3!J9),ParseTime(RunTime4!J9)) -> 0.56437823 | U9: vcf2fasta-rust Validation Passed; vcflib Validation Passed
A10: Platinum | B10: chr5 | C10: NA12877 | D10: 243732 | E10: 2 | F10: 15s 926ms | G10: 5s 976ms | H10: 2s 852ms | I10: 3s 885ms | J10: 4s 422ms | K10: 2.09x | L10: 2.66x | M10: 5.58x | N10: .87x | O10: =AVERAGE(ParseTime(RunTime1!F10),ParseTime(RunTime2!F10),ParseTime(RunTime3!F10),ParseTime(RunTime4!F10)) / AVERAGE(ParseTime(RunTime1!J10),ParseTime(RunTime2!J10),ParseTime(RunTime3!J10),ParseTime(RunTime4!J10)) -> 2.7974369 | P10: =AVERAGE(ParseTime(RunTime1!F10),ParseTime(RunTime2!F10),ParseTime(RunTime3!F10),ParseTime(RunTime4!F10)) / AVERAGE(ParseTime(RunTime1!I10),ParseTime(RunTime2!I10),ParseTime(RunTime3!I10),ParseTime(RunTime4!I10)) -> 3.2053038 | Q10: =AVERAGE(ParseTime(RunTime1!H10),ParseTime(RunTime2!H10),ParseTime(RunTime3!H10),ParseTime(RunTime4!H10)) / AVERAGE(ParseTime(RunTime1!J10),ParseTime(RunTime2!J10),ParseTime(RunTime3!J10),ParseTime(RunTime4!J10)) -> 0.92712318 | R10: =AVERAGE(ParseTime(RunTime1!G10),ParseTime(RunTime2!G10),ParseTime(RunTime3!G10),ParseTime(RunTime4!G10)) / AVERAGE(ParseTime(RunTime1!I10),ParseTime(RunTime2!I10),ParseTime(RunTime3!I10),ParseTime(RunTime4!I10)) -> 1.0537505 | S10: =AVERAGE(ParseTime(RunTime1!H10),ParseTime(RunTime2!H10),ParseTime(RunTime3!H10),ParseTime(RunTime4!H10)) / AVERAGE(ParseTime(RunTime1!I10),ParseTime(RunTime2!I10),ParseTime(RunTime3!I10),ParseTime(RunTime4!I10)) -> 1.062298 | T10: =AVERAGE(ParseTime(RunTime1!G10),ParseTime(RunTime2!G10),ParseTime(RunTime3!G10),ParseTime(RunTime4!G10)) / AVERAGE(ParseTime(RunTime1!J10),ParseTime(RunTime2!J10),ParseTime(RunTime3!J10),ParseTime(RunTime4!J10)) -> 0.91966335 | U10: vcf2fasta-rust Validation Passed; vcflib Validation Passed
A11: Platinum | B11: chr5 | C11: NA12878 | D11: 251509 | E11: 2 | F11: 14s 898ms | G11: 3s 821ms | H11: 4s 58ms | I11: 3s 864ms | J11: 6s 130ms | K11: .94x | L11: 3.89x | M11: 3.67x | N11: .63x | O11: =AVERAGE(ParseTime(RunTime1!F11),ParseTime(RunTime2!F11),ParseTime(RunTime3!F11),ParseTime(RunTime4!F11)) / AVERAGE(ParseTime(RunTime1!J11),ParseTime(RunTime2!J11),ParseTime(RunTime3!J11),ParseTime(RunTime4!J11)) -> 2.8910789 | P11: =AVERAGE(ParseTime(RunTime1!F11),ParseTime(RunTime2!F11),ParseTime(RunTime3!F11),ParseTime(RunTime4!F11)) / AVERAGE(ParseTime(RunTime1!I11),ParseTime(RunTime2!I11),ParseTime(RunTime3!I11),ParseTime(RunTime4!I11)) -> 3.1998173 | Q11: =AVERAGE(ParseTime(RunTime1!H11),ParseTime(RunTime2!H11),ParseTime(RunTime3!H11),ParseTime(RunTime4!H11)) / AVERAGE(ParseTime(RunTime1!J11),ParseTime(RunTime2!J11),ParseTime(RunTime3!J11),ParseTime(RunTime4!J11)) -> 0.88468087 | R11: =AVERAGE(ParseTime(RunTime1!G11),ParseTime(RunTime2!G11),ParseTime(RunTime3!G11),ParseTime(RunTime4!G11)) / AVERAGE(ParseTime(RunTime1!I11),ParseTime(RunTime2!I11),ParseTime(RunTime3!I11),ParseTime(RunTime4!I11)) -> 0.71960482 | S11: =AVERAGE(ParseTime(RunTime1!H11),ParseTime(RunTime2!H11),ParseTime(RunTime3!H11),ParseTime(RunTime4!H11)) / AVERAGE(ParseTime(RunTime1!I11),ParseTime(RunTime2!I11),ParseTime(RunTime3!I11),ParseTime(RunTime4!I11)) -> 0.97915596 | T11: =AVERAGE(ParseTime(RunTime1!G11),ParseTime(RunTime2!G11),ParseTime(RunTime3!G11),ParseTime(RunTime4!G11)) / AVERAGE(ParseTime(RunTime1!J11),ParseTime(RunTime2!J11),ParseTime(RunTime3!J11),ParseTime(RunTime4!J11)) -> 0.65017285 | U11: vcf2fasta-rust Validation Passed; vcflib Validation Passed
A12: Platinum | B12: chr6 | C12: NA12877 | D12: 259612 | E12: 2 | F12: 9s 364ms | G12: 4s 261ms | H12: 5s 801ms | I12: 5s 127ms | J12: 4s 184ms | K12: .73x | L12: 2.19x | M12: 1.61x | N12: 1.22x | O12: =AVERAGE(ParseTime(RunTime1!F12),ParseTime(RunTime2!F12),ParseTime(RunTime3!F12),ParseTime(RunTime4!F12)) / AVERAGE(ParseTime(RunTime1!J12),ParseTime(RunTime2!J12),ParseTime(RunTime3!J12),ParseTime(RunTime4!J12)) -> 1.8810278 | P12: =AVERAGE(ParseTime(RunTime1!F12),ParseTime(RunTime2!F12),ParseTime(RunTime3!F12),ParseTime(RunTime4!F12)) / AVERAGE(ParseTime(RunTime1!I12),ParseTime(RunTime2!I12),ParseTime(RunTime3!I12),ParseTime(RunTime4!I12)) -> 1.9180472 | Q12: =AVERAGE(ParseTime(RunTime1!H12),ParseTime(RunTime2!H12),ParseTime(RunTime3!H12),ParseTime(RunTime4!H12)) / AVERAGE(ParseTime(RunTime1!J12),ParseTime(RunTime2!J12),ParseTime(RunTime3!J12),ParseTime(RunTime4!J12)) -> 1.0412514 | R12: =AVERAGE(ParseTime(RunTime1!G12),ParseTime(RunTime2!G12),ParseTime(RunTime3!G12),ParseTime(RunTime4!G12)) / AVERAGE(ParseTime(RunTime1!I12),ParseTime(RunTime2!I12),ParseTime(RunTime3!I12),ParseTime(RunTime4!I12)) -> 0.92492069 | S12: =AVERAGE(ParseTime(RunTime1!H12),ParseTime(RunTime2!H12),ParseTime(RunTime3!H12),ParseTime(RunTime4!H12)) / AVERAGE(ParseTime(RunTime1!I12),ParseTime(RunTime2!I12),ParseTime(RunTime3!I12),ParseTime(RunTime4!I12)) -> 1.0617436 | T12: =AVERAGE(ParseTime(RunTime1!G12),ParseTime(RunTime2!G12),ParseTime(RunTime3!G12),ParseTime(RunTime4!G12)) / AVERAGE(ParseTime(RunTime1!J12),ParseTime(RunTime2!J12),ParseTime(RunTime3!J12),ParseTime(RunTime4!J12)) -> 0.90706919 | U12: vcf2fasta-rust Validation Passed; vcflib Validation Passed
A13: Platinum | B13: chr6 | C13: NA12878 | D13: 265657 | E13: 2 | F13: 9s 680ms | G13: 2s 789ms | H13: 5s 569ms | I13: 3s 922ms | J13: 4s 183ms | K13: .50x | L13: 3.47x | M13: 1.73x | N13: .93x | O13: =AVERAGE(ParseTime(RunTime1!F13),ParseTime(RunTime2!F13),ParseTime(RunTime3!F13),ParseTime(RunTime4!F13)) / AVERAGE(ParseTime(RunTime1!J13),ParseTime(RunTime2!J13),ParseTime(RunTime3!J13),ParseTime(RunTime4!J13)) -> 1.52872 | P13: =AVERAGE(ParseTime(RunTime1!F13),ParseTime(RunTime2!F13),ParseTime(RunTime3!F13),ParseTime(RunTime4!F13)) / AVERAGE(ParseTime(RunTime1!I13),ParseTime(RunTime2!I13),ParseTime(RunTime3!I13),ParseTime(RunTime4!I13)) -> 2.1031359 | Q13: =AVERAGE(ParseTime(RunTime1!H13),ParseTime(RunTime2!H13),ParseTime(RunTime3!H13),ParseTime(RunTime4!H13)) / AVERAGE(ParseTime(RunTime1!J13),ParseTime(RunTime2!J13),ParseTime(RunTime3!J13),ParseTime(RunTime4!J13)) -> 0.88952459 | R13: =AVERAGE(ParseTime(RunTime1!G13),ParseTime(RunTime2!G13),ParseTime(RunTime3!G13),ParseTime(RunTime4!G13)) / AVERAGE(ParseTime(RunTime1!I13),ParseTime(RunTime2!I13),ParseTime(RunTime3!I13),ParseTime(RunTime4!I13)) -> 0.73069715 | S13: =AVERAGE(ParseTime(RunTime1!H13),ParseTime(RunTime2!H13),ParseTime(RunTime3!H13),ParseTime(RunTime4!H13)) / AVERAGE(ParseTime(RunTime1!I13),ParseTime(RunTime2!I13),ParseTime(RunTime3!I13),ParseTime(RunTime4!I13)) -> 1.2237631 | T13: =AVERAGE(ParseTime(RunTime1!G13),ParseTime(RunTime2!G13),ParseTime(RunTime3!G13),ParseTime(RunTime4!G13)) / AVERAGE(ParseTime(RunTime1!J13),ParseTime(RunTime2!J13),ParseTime(RunTime3!J13),ParseTime(RunTime4!J13)) -> 0.53112655 | U13: vcf2fasta-rust Validation Passed; vcflib Validation Passed
A14: Platinum | B14: chr7 | C14: NA12877 | D14: 235305 | E14: 2 | F14: 9s 865ms | G14: 3s 254ms | H14: 3s 438ms | I14: 3s 889ms | J14: 5s 510ms | K14: .94x | L14: 3.03x | M14: 2.86x | N14: .70x | O14: =AVERAGE(ParseTime(RunTime1!F14),ParseTime(RunTime2!F14),ParseTime(RunTime3!F14),ParseTime(RunTime4!F14)) / AVERAGE(ParseTime(RunTime1!J14),ParseTime(RunTime2!J14),ParseTime(RunTime3!J14),ParseTime(RunTime4!J14)) -> 1.6537028 | P14: =AVERAGE(ParseTime(RunTime1!F14),ParseTime(RunTime2!F14),ParseTime(RunTime3!F14),ParseTime(RunTime4!F14)) / AVERAGE(ParseTime(RunTime1!I14),ParseTime(RunTime2!I14),ParseTime(RunTime3!I14),ParseTime(RunTime4!I14)) -> 2.3493046 | Q14: =AVERAGE(ParseTime(RunTime1!H14),ParseTime(RunTime2!H14),ParseTime(RunTime3!H14),ParseTime(RunTime4!H14)) / AVERAGE(ParseTime(RunTime1!J14),ParseTime(RunTime2!J14),ParseTime(RunTime3!J14),ParseTime(RunTime4!J14)) -> 0.69582791 | R14: =AVERAGE(ParseTime(RunTime1!G14),ParseTime(RunTime2!G14),ParseTime(RunTime3!G14),ParseTime(RunTime4!G14)) / AVERAGE(ParseTime(RunTime1!I14),ParseTime(RunTime2!I14),ParseTime(RunTime3!I14),ParseTime(RunTime4!I14)) -> 0.78422866 | S14: =AVERAGE(ParseTime(RunTime1!H14),ParseTime(RunTime2!H14),ParseTime(RunTime3!H14),ParseTime(RunTime4!H14)) / AVERAGE(ParseTime(RunTime1!I14),ParseTime(RunTime2!I14),ParseTime(RunTime3!I14),ParseTime(RunTime4!I14)) -> 0.98851601 | T14: =AVERAGE(ParseTime(RunTime1!G14),ParseTime(RunTime2!G14),ParseTime(RunTime3!G14),ParseTime(RunTime4!G14)) / AVERAGE(ParseTime(RunTime1!J14),ParseTime(RunTime2!J14),ParseTime(RunTime3!J14),ParseTime(RunTime4!J14)) -> 0.55202766 | U14: vcf2fasta-rust Validation Passed; vcflib Validation Passed
A15: Platinum | B15: chr7 | C15: NA12878 | D15: 233608 | E15: 2 | F15: 9s 464ms | G15: 2s 611ms | H15: 2s 586ms | I15: 4s 747ms | J15: 4s 192ms | K15: 1.00x | L15: 3.62x | M15: 3.66x | N15: 1.13x | O15: =AVERAGE(ParseTime(RunTime1!F15),ParseTime(RunTime2!F15),ParseTime(RunTime3!F15),ParseTime(RunTime4!F15)) / AVERAGE(ParseTime(RunTime1!J15),ParseTime(RunTime2!J15),ParseTime(RunTime3!J15),ParseTime(RunTime4!J15)) -> 1.7054108 | P15: =AVERAGE(ParseTime(RunTime1!F15),ParseTime(RunTime2!F15),ParseTime(RunTime3!F15),ParseTime(RunTime4!F15)) / AVERAGE(ParseTime(RunTime1!I15),ParseTime(RunTime2!I15),ParseTime(RunTime3!I15),ParseTime(RunTime4!I15)) -> 2.0313899 | Q15: =AVERAGE(ParseTime(RunTime1!H15),ParseTime(RunTime2!H15),ParseTime(RunTime3!H15),ParseTime(RunTime4!H15)) / AVERAGE(ParseTime(RunTime1!J15),ParseTime(RunTime2!J15),ParseTime(RunTime3!J15),ParseTime(RunTime4!J15)) -> 0.93892786 | R15: =AVERAGE(ParseTime(RunTime1!G15),ParseTime(RunTime2!G15),ParseTime(RunTime3!G15),ParseTime(RunTime4!G15)) / AVERAGE(ParseTime(RunTime1!I15),ParseTime(RunTime2!I15),ParseTime(RunTime3!I15),ParseTime(RunTime4!I15)) -> 0.61257982 | S15: =AVERAGE(ParseTime(RunTime1!H15),ParseTime(RunTime2!H15),ParseTime(RunTime3!H15),ParseTime(RunTime4!H15)) / AVERAGE(ParseTime(RunTime1!I15),ParseTime(RunTime2!I15),ParseTime(RunTime3!I15),ParseTime(RunTime4!I15)) -> 1.1183983 | T15: =AVERAGE(ParseTime(RunTime1!G15),ParseTime(RunTime2!G15),ParseTime(RunTime3!G15),ParseTime(RunTime4!G15)) / AVERAGE(ParseTime(RunTime1!J15),ParseTime(RunTime2!J15),ParseTime(RunTime3!J15),ParseTime(RunTime4!J15)) -> 0.51427856 | U15: vcf2fasta-rust Validation Passed; vcflib Validation Passed
A16: Platinum | B16: chr8 | C16: NA12877 | D16: 222180 | E16: 2 | F16: 6s 15ms | G16: 4s 663ms | H16: 2s 339ms | I16: 3s 601ms | J16: 3s 671ms | K16: 1.99x | L16: 1.29x | M16: 2.57x | N16: .98x | O16: =AVERAGE(ParseTime(RunTime1!F16),ParseTime(RunTime2!F16),ParseTime(RunTime3!F16),ParseTime(RunTime4!F16)) / AVERAGE(ParseTime(RunTime1!J16),ParseTime(RunTime2!J16),ParseTime(RunTime3!J16),ParseTime(RunTime4!J16)) -> 1.6240389 | P16: =AVERAGE(ParseTime(RunTime1!F16),ParseTime(RunTime2!F16),ParseTime(RunTime3!F16),ParseTime(RunTime4!F16)) / AVERAGE(ParseTime(RunTime1!I16),ParseTime(RunTime2!I16),ParseTime(RunTime3!I16),ParseTime(RunTime4!I16)) -> 1.7224232 | Q16: =AVERAGE(ParseTime(RunTime1!H16),ParseTime(RunTime2!H16),ParseTime(RunTime3!H16),ParseTime(RunTime4!H16)) / AVERAGE(ParseTime(RunTime1!J16),ParseTime(RunTime2!J16),ParseTime(RunTime3!J16),ParseTime(RunTime4!J16)) -> 0.9948546 | R16: =AVERAGE(ParseTime(RunTime1!G16),ParseTime(RunTime2!G16),ParseTime(RunTime3!G16),ParseTime(RunTime4!G16)) / AVERAGE(ParseTime(RunTime1!I16),ParseTime(RunTime2!I16),ParseTime(RunTime3!I16),ParseTime(RunTime4!I16)) -> 0.80495432 | S16: =AVERAGE(ParseTime(RunTime1!H16),ParseTime(RunTime2!H16),ParseTime(RunTime3!H16),ParseTime(RunTime4!H16)) / AVERAGE(ParseTime(RunTime1!I16),ParseTime(RunTime2!I16),ParseTime(RunTime3!I16),ParseTime(RunTime4!I16)) -> 1.0551229 | T16: =AVERAGE(ParseTime(RunTime1!G16),ParseTime(RunTime2!G16),ParseTime(RunTime3!G16),ParseTime(RunTime4!G16)) / AVERAGE(ParseTime(RunTime1!J16),ParseTime(RunTime2!J16),ParseTime(RunTime3!J16),ParseTime(RunTime4!J16)) -> 0.75897554 | U16: vcf2fasta-rust Validation Passed; vcflib Validation Passed
A17: Platinum | B17: chr8 | C17: NA12878 | D17: 215330 | E17: 2 | F17: 6s 235ms | G17: 2s 400ms | H17: 5s 897ms | I17: 3s 266ms | J17: 3s 675ms | K17: .40x | L17: 2.59x | M17: 1.05x | N17: .88x | O17: =AVERAGE(ParseTime(RunTime1!F17),ParseTime(RunTime2!F17),ParseTime(RunTime3!F17),ParseTime(RunTime4!F17)) / AVERAGE(ParseTime(RunTime1!J17),ParseTime(RunTime2!J17),ParseTime(RunTime3!J17),ParseTime(RunTime4!J17)) -> 1.3993248 | P17: =AVERAGE(ParseTime(RunTime1!F17),ParseTime(RunTime2!F17),ParseTime(RunTime3!F17),ParseTime(RunTime4!F17)) / AVERAGE(ParseTime(RunTime1!I17),ParseTime(RunTime2!I17),ParseTime(RunTime3!I17),ParseTime(RunTime4!I17)) -> 1.8443183 | Q17: =AVERAGE(ParseTime(RunTime1!H17),ParseTime(RunTime2!H17),ParseTime(RunTime3!H17),ParseTime(RunTime4!H17)) / AVERAGE(ParseTime(RunTime1!J17),ParseTime(RunTime2!J17),ParseTime(RunTime3!J17),ParseTime(RunTime4!J17)) -> 0.93448158 | R17: =AVERAGE(ParseTime(RunTime1!G17),ParseTime(RunTime2!G17),ParseTime(RunTime3!G17),ParseTime(RunTime4!G17)) / AVERAGE(ParseTime(RunTime1!I17),ParseTime(RunTime2!I17),ParseTime(RunTime3!I17),ParseTime(RunTime4!I17)) -> 0.65510125 | S17: =AVERAGE(ParseTime(RunTime1!H17),ParseTime(RunTime2!H17),ParseTime(RunTime3!H17),ParseTime(RunTime4!H17)) / AVERAGE(ParseTime(RunTime1!I17),ParseTime(RunTime2!I17),ParseTime(RunTime3!I17),ParseTime(RunTime4!I17)) -> 1.2316523 | T17: =AVERAGE(ParseTime(RunTime1!G17),ParseTime(RunTime2!G17),ParseTime(RunTime3!G17),ParseTime(RunTime4!G17)) / AVERAGE(ParseTime(RunTime1!J17),ParseTime(RunTime2!J17),ParseTime(RunTime3!J17),ParseTime(RunTime4!J17)) -> 0.49703968 | U17: vcf2fasta-rust Validation Passed; vcflib Validation Passed
... A47: Platinum | B47: chrX | C47: NA12878 | D47: 127106 | E47: 2 | F47: 17s 666ms | G47: 2s 354ms | H47: 5s 808ms | I47: 4s 697ms | J47: 3s 828ms | K47: .40x | L47: 7.50x | M47: 3.04x | N47: 1.22x | O47: =AVERAGE(ParseTime(RunTime1!F47),ParseTime(RunTime2!F47),ParseTime(RunTime3!F47),ParseTime(RunTime4!F47)) / AVERAGE(ParseTime(RunTime1!J47),ParseTime(RunTime2!J47),ParseTime(RunTime3!J47),ParseTime(RunTime4!J47)) -> 4.5500195 | P47: =AVERAGE(ParseTime(RunTime1!F47),ParseTime(RunTime2!F47),ParseTime(RunTime3!F47),ParseTime(RunTime4!F47)) / AVERAGE(ParseTime(RunTime1!I47),ParseTime(RunTime2!I47),ParseTime(RunTime3!I47),ParseTime(RunTime4!I47)) -> 4.2722171 | Q47: =AVERAGE(ParseTime(RunTime1!H47),ParseTime(RunTime2!H47),ParseTime(RunTime3!H47),ParseTime(RunTime4!H47)) / AVERAGE(ParseTime(RunTime1!J47),ParseTime(RunTime2!J47),ParseTime(RunTime3!J47),ParseTime(RunTime4!J47)) -> 1.2289204 | R47: =AVERAGE(ParseTime(RunTime1!G47),ParseTime(RunTime2!G47),ParseTime(RunTime3!G47),ParseTime(RunTime4!G47)) / AVERAGE(ParseTime(RunTime1!I47),ParseTime(RunTime2!I47),ParseTime(RunTime3!I47),ParseTime(RunTime4!I47)) -> 0.56078073 | S47: =AVERAGE(ParseTime(RunTime1!H47),ParseTime(RunTime2!H47),ParseTime(RunTime3!H47),ParseTime(RunTime4!H47)) / AVERAGE(ParseTime(RunTime1!I47),ParseTime(RunTime2!I47),ParseTime(RunTime3!I47),ParseTime(RunTime4!I47)) -> 1.1538884 | T47: =AVERAGE(ParseTime(RunTime1!G47),ParseTime(RunTime2!G47),ParseTime(RunTime3!G47),ParseTime(RunTime4!G47)) / AVERAGE(ParseTime(RunTime1!J47),ParseTime(RunTime2!J47),ParseTime(RunTime3!J47),ParseTime(RunTime4!J47)) -> 0.59724568 | U47: vcf2fasta-rust Validation Passed; vcflib Validation Passed

Sheet RunTime2
A1: Dataset | B1: Chromosome | C1: Sample | D1: Variants | E1: Ploidy | F1: vcflib | G1: cpu_t1_time | H1: cpu_t2_time | I1: gpu_t1_time | J1: gpu_t2_time | K1: speedup_cpu_t2_vs_t1 | L1: speedup_cpu_t1_vs_vcflib | M1: speedup_cpu_t2_vs_vcflib | N1: speedup_gpu_t2_vs_t1 | O1: speedup_gpu_t2_vs_vcflib | P1: speedup_gpu_t1_vs_vcflib | Q1: speedup_gpu_t2_vs_cpu_t2 | R1: speedup_gpu_t1_vs_cpu_t1 | S1: speedup_gpu_t1_vs_cpu_t2 | T1: speedup_gpu_t2_vs_cpu_t1 | U1: Notes
A2: Platinum | B2: chr1 | C2: NA12877 | D2: 319247 | E2: 2 | F2: 12m 45s 197ms | G2: 6s 759ms | H2: 5s 614ms | I2: 5s 162ms | J2: 6s 170ms | K2: 1.20x | L2: 113.21x | M2: 136.29x | N2: .83x | O2: =AVERAGE(ParseTime(RunTime1!F2),ParseTime(RunTime2!F2),ParseTime(RunTime3!F2),ParseTime(RunTime4!F2)) / AVERAGE(ParseTime(RunTime1!J2),ParseTime(RunTime2!J2),ParseTime(RunTime3!J2),ParseTime(RunTime4!J2)) -> 140.80047 | P2: =AVERAGE(ParseTime(RunTime1!F2),ParseTime(RunTime2!F2),ParseTime(RunTime3!F2),ParseTime(RunTime4!F2)) / AVERAGE(ParseTime(RunTime1!I2),ParseTime(RunTime2!I2),ParseTime(RunTime3!I2),ParseTime(RunTime4!I2)) -> 150.16231 | Q2: =AVERAGE(ParseTime(RunTime1!H2),ParseTime(RunTime2!H2),ParseTime(RunTime3!H2),ParseTime(RunTime4!H2)) / AVERAGE(ParseTime(RunTime1!J2),ParseTime(RunTime2!J2),ParseTime(RunTime3!J2),ParseTime(RunTime4!J2)) -> 1.0387539 | R2: =AVERAGE(ParseTime(RunTime1!G2),ParseTime(RunTime2!G2),ParseTime(RunTime3!G2),ParseTime(RunTime4!G2)) / AVERAGE(ParseTime(RunTime1!I2),ParseTime(RunTime2!I2),ParseTime(RunTime3!I2),ParseTime(RunTime4!I2)) -> 1.0428153 | S2: =AVERAGE(ParseTime(RunTime1!H2),ParseTime(RunTime2!H2),ParseTime(RunTime3!H2),ParseTime(RunTime4!H2)) / AVERAGE(ParseTime(RunTime1!I2),ParseTime(RunTime2!I2),ParseTime(RunTime3!I2),ParseTime(RunTime4!I2)) -> 1.1078207 | T2: =AVERAGE(ParseTime(RunTime1!G2),ParseTime(RunTime2!G2),ParseTime(RunTime3!G2),ParseTime(RunTime4!G2)) / AVERAGE(ParseTime(RunTime1!J2),ParseTime(RunTime2!J2),ParseTime(RunTime3!J2),ParseTime(RunTime4!J2)) -> 0.97780119 | U2: vcf2fasta-rust Validation Passed; vcflib Validation Passed
A3: Platinum | B3: chr1 | C3: NA12878 | D3: 316061 | E3: 2 | F3: 12m 48s 639ms | G3: 6s 359ms | H3: 7s 25ms | I3: 6s 27ms | J3: 5s 923ms | K3: .90x | L3: 120.87x | M3: 109.40x | N3: 1.01x | O3: =AVERAGE(ParseTime(RunTime1!F3),ParseTime(RunTime2!F3),ParseTime(RunTime3!F3),ParseTime(RunTime4!F3)) / AVERAGE(ParseTime(RunTime1!J3),ParseTime(RunTime2!J3),ParseTime(RunTime3!J3),ParseTime(RunTime4!J3)) -> 121.73841 | P3: =AVERAGE(ParseTime(RunTime1!F3),ParseTime(RunTime2!F3),ParseTime(RunTime3!F3),ParseTime(RunTime4!F3)) / AVERAGE(ParseTime(RunTime1!I3),ParseTime(RunTime2!I3),ParseTime(RunTime3!I3),ParseTime(RunTime4!I3)) -> 131.53884 | Q3: =AVERAGE(ParseTime(RunTime1!H3),ParseTime(RunTime2!H3),ParseTime(RunTime3!H3),ParseTime(RunTime4!H3)) / AVERAGE(ParseTime(RunTime1!J3),ParseTime(RunTime2!J3),ParseTime(RunTime3!J3),ParseTime(RunTime4!J3)) -> 0.94838583 | R3: =AVERAGE(ParseTime(RunTime1!G3),ParseTime(RunTime2!G3),ParseTime(RunTime3!G3),ParseTime(RunTime4!G3)) / AVERAGE(ParseTime(RunTime1!I3),ParseTime(RunTime2!I3),ParseTime(RunTime3!I3),ParseTime(RunTime4!I3)) -> 1.1331022 | S3: =AVERAGE(ParseTime(RunTime1!H3),ParseTime(RunTime2!H3),ParseTime(RunTime3!H3),ParseTime(RunTime4!H3)) / AVERAGE(ParseTime(RunTime1!I3),ParseTime(RunTime2!I3),ParseTime(RunTime3!I3),ParseTime(RunTime4!I3)) -> 1.0247347 | T3: =AVERAGE(ParseTime(RunTime1!G3),ParseTime(RunTime2!G3),ParseTime(RunTime3!G3),ParseTime(RunTime4!G3)) / AVERAGE(ParseTime(RunTime1!J3),ParseTime(RunTime2!J3),ParseTime(RunTime3!J3),ParseTime(RunTime4!J3)) -> 1.0486793 | U3: vcf2fasta-rust Validation Passed; vcflib Validation Passed
A4: Platinum | B4: chr2 | C4: NA12877 | D4: 328730 | E4: 2 | F4: 14s 183ms | G4: 8s 483ms | H4: 4s 975ms | I4: 7s 754ms | J4: 7s 535ms | K4: 1.70x | L4: 1.67x | M4: 2.85x | N4: 1.02x | O4: =AVERAGE(ParseTime(RunTime1!F4),ParseTime(RunTime2!F4),ParseTime(RunTime3!F4),ParseTime(RunTime4!F4)) / AVERAGE(ParseTime(RunTime1!J4),ParseTime(RunTime2!J4),ParseTime(RunTime3!J4),ParseTime(RunTime4!J4)) -> 2.2017179 | P4: =AVERAGE(ParseTime(RunTime1!F4),ParseTime(RunTime2!F4),ParseTime(RunTime3!F4),ParseTime(RunTime4!F4)) / AVERAGE(ParseTime(RunTime1!I4),ParseTime(RunTime2!I4),ParseTime(RunTime3!I4),ParseTime(RunTime4!I4)) -> 2.4598652 | Q4: =AVERAGE(ParseTime(RunTime1!H4),ParseTime(RunTime2!H4),ParseTime(RunTime3!H4),ParseTime(RunTime4!H4)) / AVERAGE(ParseTime(RunTime1!J4),ParseTime(RunTime2!J4),ParseTime(RunTime3!J4),ParseTime(RunTime4!J4)) -> 0.75697652 | R4: =AVERAGE(ParseTime(RunTime1!G4),ParseTime(RunTime2!G4),ParseTime(RunTime3!G4),ParseTime(RunTime4!G4)) / AVERAGE(ParseTime(RunTime1!I4),ParseTime(RunTime2!I4),ParseTime(RunTime3!I4),ParseTime(RunTime4!I4)) -> 1.1201058 | S4: =AVERAGE(ParseTime(RunTime1!H4),ParseTime(RunTime2!H4),ParseTime(RunTime3!H4),ParseTime(RunTime4!H4)) / AVERAGE(ParseTime(RunTime1!I4),ParseTime(RunTime2!I4),ParseTime(RunTime3!I4),ParseTime(RunTime4!I4)) -> 0.84573062 | T4: =AVERAGE(ParseTime(RunTime1!G4),ParseTime(RunTime2!G4),ParseTime(RunTime3!G4),ParseTime(RunTime4!G4)) / AVERAGE(ParseTime(RunTime1!J4),ParseTime(RunTime2!J4),ParseTime(RunTime3!J4),ParseTime(RunTime4!J4)) -> 1.0025577 | U4: vcf2fasta-rust Validation Passed; vcflib Validation Passed
A5: Platinum | B5: chr2 | C5: NA12878 | D5: 335402 | E5: 2 | F5: N/A | G5: 3s 816ms | H5: 5s 949ms | I5: 5s 618ms | J5: 5s 517ms | K5: .64x | L5: N/A | M5: N/A | N5: 1.01x | O5: N/A | P5: N/A | Q5: =AVERAGE(ParseTime(RunTime1!H5),ParseTime(RunTime2!H5),ParseTime(RunTime3!H5),ParseTime(RunTime4!H5)) / AVERAGE(ParseTime(RunTime1!J5),ParseTime(RunTime2!J5),ParseTime(RunTime3!J5),ParseTime(RunTime4!J5)) -> 1.1001145 | R5: =AVERAGE(ParseTime(RunTime1!G5),ParseTime(RunTime2!G5),ParseTime(RunTime3!G5),ParseTime(RunTime4!G5)) / AVERAGE(ParseTime(RunTime1!I5),ParseTime(RunTime2!I5),ParseTime(RunTime3!I5),ParseTime(RunTime4!I5)) -> 0.79399302 | S5: =AVERAGE(ParseTime(RunTime1!H5),ParseTime(RunTime2!H5),ParseTime(RunTime3!H5),ParseTime(RunTime4!H5)) / AVERAGE(ParseTime(RunTime1!I5),ParseTime(RunTime2!I5),ParseTime(RunTime3!I5),ParseTime(RunTime4!I5)) -> 1.0375955 | T5: =AVERAGE(ParseTime(RunTime1!G5),ParseTime(RunTime2!G5),ParseTime(RunTime3!G5),ParseTime(RunTime4!G5)) / AVERAGE(ParseTime(RunTime1!J5),ParseTime(RunTime2!J5),ParseTime(RunTime3!J5),ParseTime(RunTime4!J5)) -> 0.84183404 | U5: vcf2fasta-rust Validation Passed (SKIPPED chr2:118112315 REF=AAAAT ALT=A GT=0|1 reason=overlap); vcflib Validation Failed (due to overlap)
A6: Platinum | B6: chr3 | C6: NA12877 | D6: 284815 | E6: 2 | F6: 8s 833ms | G6: 4s 526ms | H6: 4s 437ms | I6: 4s 335ms | J6: 6s 372ms | K6: 1.02x | L6: 1.95x | M6: 1.99x | N6: .68x | O6: =AVERAGE(ParseTime(RunTime1!F6),ParseTime(RunTime2!F6),ParseTime(RunTime3!F6),ParseTime(RunTime4!F6)) / AVERAGE(ParseTime(RunTime1!J6),ParseTime(RunTime2!J6),ParseTime(RunTime3!J6),ParseTime(RunTime4!J6)) -> 1.4791844 | P6: =AVERAGE(ParseTime(RunTime1!F6),ParseTime(RunTime2!F6),ParseTime(RunTime3!F6),ParseTime(RunTime4!F6)) / AVERAGE(ParseTime(RunTime1!I6),ParseTime(RunTime2!I6),ParseTime(RunTime3!I6),ParseTime(RunTime4!I6)) -> 1.8409366 | Q6: =AVERAGE(ParseTime(RunTime1!H6),ParseTime(RunTime2!H6),ParseTime(RunTime3!H6),ParseTime(RunTime4!H6)) / AVERAGE(ParseTime(RunTime1!J6),ParseTime(RunTime2!J6),ParseTime(RunTime3!J6),ParseTime(RunTime4!J6)) -> 0.99510458 | R6: =AVERAGE(ParseTime(RunTime1!G6),ParseTime(RunTime2!G6),ParseTime(RunTime3!G6),ParseTime(RunTime4!G6)) / AVERAGE(ParseTime(RunTime1!I6),ParseTime(RunTime2!I6),ParseTime(RunTime3!I6),ParseTime(RunTime4!I6)) -> 0.92628399 | S6: =AVERAGE(ParseTime(RunTime1!H6),ParseTime(RunTime2!H6),ParseTime(RunTime3!H6),ParseTime(RunTime4!H6)) / AVERAGE(ParseTime(RunTime1!I6),ParseTime(RunTime2!I6),ParseTime(RunTime3!I6),ParseTime(RunTime4!I6)) -> 1.2384693 | T6: =AVERAGE(ParseTime(RunTime1!G6),ParseTime(RunTime2!G6),ParseTime(RunTime3!G6),ParseTime(RunTime4!G6)) / AVERAGE(ParseTime(RunTime1!J6),ParseTime(RunTime2!J6),ParseTime(RunTime3!J6),ParseTime(RunTime4!J6)) -> 0.74426508 | U6: vcf2fasta-rust Validation Passed; vcflib Validation Passed
A7: Platinum | B7: chr3 | C7: NA12878 | D7: 280114 | E7: 2 | F7: 8s 15ms | G7: 3s 183ms | H7: 5s 685ms | I7: 5s 857ms | J7: 6s 986ms | K7: .55x | L7: 2.51x | M7: 1.40x | N7: .83x | O7: =AVERAGE(ParseTime(RunTime1!F7),ParseTime(RunTime2!F7),ParseTime(RunTime3!F7),ParseTime(RunTime4!F7)) / AVERAGE(ParseTime(RunTime1!J7),ParseTime(RunTime2!J7),ParseTime(RunTime3!J7),ParseTime(RunTime4!J7)) -> 0.58038042 | P7: =AVERAGE(ParseTime(RunTime1!F7),ParseTime(RunTime2!F7),ParseTime(RunTime3!F7),ParseTime(RunTime4!F7)) / AVERAGE(ParseTime(RunTime1!I7),ParseTime(RunTime2!I7),ParseTime(RunTime3!I7),ParseTime(RunTime4!I7)) -> 1.9006989 | Q7: =AVERAGE(ParseTime(RunTime1!H7),ParseTime(RunTime2!H7),ParseTime(RunTime3!H7),ParseTime(RunTime4!H7)) / AVERAGE(ParseTime(RunTime1!J7),ParseTime(RunTime2!J7),ParseTime(RunTime3!J7),ParseTime(RunTime4!J7)) -> 0.29147211 | R7: =AVERAGE(ParseTime(RunTime1!G7),ParseTime(RunTime2!G7),ParseTime(RunTime3!G7),ParseTime(RunTime4!G7)) / AVERAGE(ParseTime(RunTime1!I7),ParseTime(RunTime2!I7),ParseTime(RunTime3!I7),ParseTime(RunTime4!I7)) -> 0.74797129 | S7: =AVERAGE(ParseTime(RunTime1!H7),ParseTime(RunTime2!H7),ParseTime(RunTime3!H7),ParseTime(RunTime4!H7)) / AVERAGE(ParseTime(RunTime1!I7),ParseTime(RunTime2!I7),ParseTime(RunTime3!I7),ParseTime(RunTime4!I7)) -> 0.95454759 | T7: =AVERAGE(ParseTime(RunTime1!G7),ParseTime(RunTime2!G7),ParseTime(RunTime3!G7),ParseTime(RunTime4!G7)) / AVERAGE(ParseTime(RunTime1!J7),ParseTime(RunTime2!J7),ParseTime(RunTime3!J7),ParseTime(RunTime4!J7)) -> 0.22839382 | U7: vcf2fasta-rust Validation Passed; vcflib Validation Passed
A8: Platinum | B8: chr4 | C8: NA12877 | D8: 306846 | E8: 2 | F8: 8s 399ms | G8: 4s 567ms | H8: 3s 755ms | I8: 4s 186ms | J8: 5s 109ms | K8: 1.21x | L8: 1.83x | M8: 2.23x | N8: .81x | O8: =AVERAGE(ParseTime(RunTime1!F8),ParseTime(RunTime2!F8),ParseTime(RunTime3!F8),ParseTime(RunTime4!F8)) / AVERAGE(ParseTime(RunTime1!J8),ParseTime(RunTime2!J8),ParseTime(RunTime3!J8),ParseTime(RunTime4!J8)) -> 1.7187418 | P8: =AVERAGE(ParseTime(RunTime1!F8),ParseTime(RunTime2!F8),ParseTime(RunTime3!F8),ParseTime(RunTime4!F8)) / AVERAGE(ParseTime(RunTime1!I8),ParseTime(RunTime2!I8),ParseTime(RunTime3!I8),ParseTime(RunTime4!I8)) -> 2.0019445 | Q8: =AVERAGE(ParseTime(RunTime1!H8),ParseTime(RunTime2!H8),ParseTime(RunTime3!H8),ParseTime(RunTime4!H8)) / AVERAGE(ParseTime(RunTime1!J8),ParseTime(RunTime2!J8),ParseTime(RunTime3!J8),ParseTime(RunTime4!J8)) -> 0.73508479 | R8: =AVERAGE(ParseTime(RunTime1!G8),ParseTime(RunTime2!G8),ParseTime(RunTime3!G8),ParseTime(RunTime4!G8)) / AVERAGE(ParseTime(RunTime1!I8),ParseTime(RunTime2!I8),ParseTime(RunTime3!I8),ParseTime(RunTime4!I8)) -> 0.92887115 | S8: =AVERAGE(ParseTime(RunTime1!H8),ParseTime(RunTime2!H8),ParseTime(RunTime3!H8),ParseTime(RunTime4!H8)) / AVERAGE(ParseTime(RunTime1!I8),ParseTime(RunTime2!I8),ParseTime(RunTime3!I8),ParseTime(RunTime4!I8)) -> 0.85620714 | T8: =AVERAGE(ParseTime(RunTime1!G8),ParseTime(RunTime2!G8),ParseTime(RunTime3!G8),ParseTime(RunTime4!G8)) / AVERAGE(ParseTime(RunTime1!J8),ParseTime(RunTime2!J8),ParseTime(RunTime3!J8),ParseTime(RunTime4!J8)) -> 0.79746947 | U8: vcf2fasta-rust Validation Passed; vcflib Validation Passed
A9: Platinum | B9: chr4 | C9: NA12878 | D9: 301639 | E9: 2 | F9: 9s 119ms | G9: 4s 896ms | H9: 3s 158ms | I9: 4s 379ms | J9: 6s 119ms | K9: 1.55x | L9: 1.86x | M9: 2.88x | N9: .71x | O9: =AVERAGE(ParseTime(RunTime1!F9),ParseTime(RunTime2!F9),ParseTime(RunTime3!F9),ParseTime(RunTime4!F9)) / AVERAGE(ParseTime(RunTime1!J9),ParseTime(RunTime2!J9),ParseTime(RunTime3!J9),ParseTime(RunTime4!J9)) -> 1.4177522 | P9: =AVERAGE(ParseTime(RunTime1!F9),ParseTime(RunTime2!F9),ParseTime(RunTime3!F9),ParseTime(RunTime4!F9)) / AVERAGE(ParseTime(RunTime1!I9),ParseTime(RunTime2!I9),ParseTime(RunTime3!I9),ParseTime(RunTime4!I9)) -> 1.9071076 | Q9: =AVERAGE(ParseTime(RunTime1!H9),ParseTime(RunTime2!H9),ParseTime(RunTime3!H9),ParseTime(RunTime4!H9)) / AVERAGE(ParseTime(RunTime1!J9),ParseTime(RunTime2!J9),ParseTime(RunTime3!J9),ParseTime(RunTime4!J9)) -> 0.71654497 | R9: =AVERAGE(ParseTime(RunTime1!G9),ParseTime(RunTime2!G9),ParseTime(RunTime3!G9),ParseTime(RunTime4!G9)) / AVERAGE(ParseTime(RunTime1!I9),ParseTime(RunTime2!I9),ParseTime(RunTime3!I9),ParseTime(RunTime4!I9)) -> 0.75918065 | S9: =AVERAGE(ParseTime(RunTime1!H9),ParseTime(RunTime2!H9),ParseTime(RunTime3!H9),ParseTime(RunTime4!H9)) / AVERAGE(ParseTime(RunTime1!I9),ParseTime(RunTime2!I9),ParseTime(RunTime3!I9),ParseTime(RunTime4!I9)) -> 0.96386969 | T9: =AVERAGE(ParseTime(RunTime1!G9),ParseTime(RunTime2!G9),ParseTime(RunTime3!G9),ParseTime(RunTime4!G9)) / AVERAGE(ParseTime(RunTime1!J9),ParseTime(RunTime2!J9),ParseTime(RunTime3!J9),ParseTime(RunTime4!J9)) -> 0.56437823 | U9: vcf2fasta-rust Validation Passed; vcflib Validation Passed
A10: Platinum | B10: chr5 | C10: NA12877 | D10: 243732 | E10: 2 | F10: 12s 871ms | G10: 4s 206ms | H10: 5s 718ms | I10: 5s 258ms | J10: 4s 255ms | K10: .73x | L10: 3.06x | M10: 2.25x | N10: 1.23x | O10: =AVERAGE(ParseTime(RunTime1!F10),ParseTime(RunTime2!F10),ParseTime(RunTime3!F10),ParseTime(RunTime4!F10)) / AVERAGE(ParseTime(RunTime1!J10),ParseTime(RunTime2!J10),ParseTime(RunTime3!J10),ParseTime(RunTime4!J10)) -> 2.7974369 | P10: =AVERAGE(ParseTime(RunTime1!F10),ParseTime(RunTime2!F10),ParseTime(RunTime3!F10),ParseTime(RunTime4!F10)) / AVERAGE(ParseTime(RunTime1!I10),ParseTime(RunTime2!I10),ParseTime(RunTime3!I10),ParseTime(RunTime4!I10)) -> 3.2053038 | Q10: =AVERAGE(ParseTime(RunTime1!H10),ParseTime(RunTime2!H10),ParseTime(RunTime3!H10),ParseTime(RunTime4!H10)) / AVERAGE(ParseTime(RunTime1!J10),ParseTime(RunTime2!J10),ParseTime(RunTime3!J10),ParseTime(RunTime4!J10)) -> 0.92712318 | R10: =AVERAGE(ParseTime(RunTime1!G10),ParseTime(RunTime2!G10),ParseTime(RunTime3!G10),ParseTime(RunTime4!G10)) / AVERAGE(ParseTime(RunTime1!I10),ParseTime(RunTime2!I10),ParseTime(RunTime3!I10),ParseTime(RunTime4!I10)) -> 1.0537505 | S10: =AVERAGE(ParseTime(RunTime1!H10),ParseTime(RunTime2!H10),ParseTime(RunTime3!H10),ParseTime(RunTime4!H10)) / AVERAGE(ParseTime(RunTime1!I10),ParseTime(RunTime2!I10),ParseTime(RunTime3!I10),ParseTime(RunTime4!I10)) -> 1.062298 | T10: =AVERAGE(ParseTime(RunTime1!G10),ParseTime(RunTime2!G10),ParseTime(RunTime3!G10),ParseTime(RunTime4!G10)) / AVERAGE(ParseTime(RunTime1!J10),ParseTime(RunTime2!J10),ParseTime(RunTime3!J10),ParseTime(RunTime4!J10)) -> 0.91966335 | U10: vcf2fasta-rust Validation Passed; vcflib Validation Passed
A11: Platinum | B11: chr5 | C11: NA12878 | D11: 251509 | E11: 2 | F11: 13s 316ms | G11: 2s 916ms | H11: 2s 880ms | I11: 4s 232ms | J11: 4s 357ms | K11: 1.01x | L11: 4.56x | M11: 4.62x | N11: .97x | O11: =AVERAGE(ParseTime(RunTime1!F11),ParseTime(RunTime2!F11),ParseTime(RunTime3!F11),ParseTime(RunTime4!F11)) / AVERAGE(ParseTime(RunTime1!J11),ParseTime(RunTime2!J11),ParseTime(RunTime3!J11),ParseTime(RunTime4!J11)) -> 2.8910789 | P11: =AVERAGE(ParseTime(RunTime1!F11),ParseTime(RunTime2!F11),ParseTime(RunTime3!F11),ParseTime(RunTime4!F11)) / AVERAGE(ParseTime(RunTime1!I11),ParseTime(RunTime2!I11),ParseTime(RunTime3!I11),ParseTime(RunTime4!I11)) -> 3.1998173 | Q11: =AVERAGE(ParseTime(RunTime1!H11),ParseTime(RunTime2!H11),ParseTime(RunTime3!H11),ParseTime(RunTime4!H11)) / AVERAGE(ParseTime(RunTime1!J11),ParseTime(RunTime2!J11),ParseTime(RunTime3!J11),ParseTime(RunTime4!J11)) -> 0.88468087 | R11: =AVERAGE(ParseTime(RunTime1!G11),ParseTime(RunTime2!G11),ParseTime(RunTime3!G11),ParseTime(RunTime4!G11)) / AVERAGE(ParseTime(RunTime1!I11),ParseTime(RunTime2!I11),ParseTime(RunTime3!I11),ParseTime(RunTime4!I11)) -> 0.71960482 | S11: =AVERAGE(ParseTime(RunTime1!H11),ParseTime(RunTime2!H11),ParseTime(RunTime3!H11),ParseTime(RunTime4!H11)) / AVERAGE(ParseTime(RunTime1!I11),ParseTime(RunTime2!I11),ParseTime(RunTime3!I11),ParseTime(RunTime4!I11)) -> 0.97915596 | T11: =AVERAGE(ParseTime(RunTime1!G11),ParseTime(RunTime2!G11),ParseTime(RunTime3!G11),ParseTime(RunTime4!G11)) / AVERAGE(ParseTime(RunTime1!J11),ParseTime(RunTime2!J11),ParseTime(RunTime3!J11),ParseTime(RunTime4!J11)) -> 0.65017285 | U11: vcf2fasta-rust Validation Passed; vcflib Validation Passed
A12: Platinum | B12: chr6 | C12: NA12877 | D12: 259612 | E12: 2 | F12: 7s 486ms | G12: 3s 169ms | H12: 5s 577ms | I12: 3s 870ms | J12: 4s 290ms | K12: .56x | L12: 2.36x | M12: 1.34x | N12: .90x | O12: =AVERAGE(ParseTime(RunTime1!F12),ParseTime(RunTime2!F12),ParseTime(RunTime3!F12),ParseTime(RunTime4!F12)) / AVERAGE(ParseTime(RunTime1!J12),ParseTime(RunTime2!J12),ParseTime(RunTime3!J12),ParseTime(RunTime4!J12)) -> 1.8810278 | P12: =AVERAGE(ParseTime(RunTime1!F12),ParseTime(RunTime2!F12),ParseTime(RunTime3!F12),ParseTime(RunTime4!F12)) / AVERAGE(ParseTime(RunTime1!I12),ParseTime(RunTime2!I12),ParseTime(RunTime3!I12),ParseTime(RunTime4!I12)) -> 1.9180472 | Q12: =AVERAGE(ParseTime(RunTime1!H12),ParseTime(RunTime2!H12),ParseTime(RunTime3!H12),ParseTime(RunTime4!H12)) / AVERAGE(ParseTime(RunTime1!J12),ParseTime(RunTime2!J12),ParseTime(RunTime3!J12),ParseTime(RunTime4!J12)) -> 1.0412514 | R12: =AVERAGE(ParseTime(RunTime1!G12),ParseTime(RunTime2!G12),ParseTime(RunTime3!G12),ParseTime(RunTime4!G12)) / AVERAGE(ParseTime(RunTime1!I12),ParseTime(RunTime2!I12),ParseTime(RunTime3!I12),ParseTime(RunTime4!I12)) -> 0.92492069 | S12: =AVERAGE(ParseTime(RunTime1!H12),ParseTime(RunTime2!H12),ParseTime(RunTime3!H12),ParseTime(RunTime4!H12)) / AVERAGE(ParseTime(RunTime1!I12),ParseTime(RunTime2!I12),ParseTime(RunTime3!I12),ParseTime(RunTime4!I12)) -> 1.0617436 | T12: =AVERAGE(ParseTime(RunTime1!G12),ParseTime(RunTime2!G12),ParseTime(RunTime3!G12),ParseTime(RunTime4!G12)) / AVERAGE(ParseTime(RunTime1!J12),ParseTime(RunTime2!J12),ParseTime(RunTime3!J12),ParseTime(RunTime4!J12)) -> 0.90706919 | U12: vcf2fasta-rust Validation Passed; vcflib Validation Passed
A13: Platinum | B13: chr6 | C13: NA12878 | D13: 265657 | E13: 2 | F13: 8s 94ms | G13: 2s 810ms | H13: 3s 948ms | I13: 3s 881ms | J13: 5s 432ms | K13: .71x | L13: 2.88x | M13: 2.05x | N13: .71x | O13: =AVERAGE(ParseTime(RunTime1!F13),ParseTime(RunTime2!F13),ParseTime(RunTime3!F13),ParseTime(RunTime4!F13)) / AVERAGE(ParseTime(RunTime1!J13),ParseTime(RunTime2!J13),ParseTime(RunTime3!J13),ParseTime(RunTime4!J13)) -> 1.52872 | P13: =AVERAGE(ParseTime(RunTime1!F13),ParseTime(RunTime2!F13),ParseTime(RunTime3!F13),ParseTime(RunTime4!F13)) / AVERAGE(ParseTime(RunTime1!I13),ParseTime(RunTime2!I13),ParseTime(RunTime3!I13),ParseTime(RunTime4!I13)) -> 2.1031359 | Q13: =AVERAGE(ParseTime(RunTime1!H13),ParseTime(RunTime2!H13),ParseTime(RunTime3!H13),ParseTime(RunTime4!H13)) / AVERAGE(ParseTime(RunTime1!J13),ParseTime(RunTime2!J13),ParseTime(RunTime3!J13),ParseTime(RunTime4!J13)) -> 0.88952459 | R13: =AVERAGE(ParseTime(RunTime1!G13),ParseTime(RunTime2!G13),ParseTime(RunTime3!G13),ParseTime(RunTime4!G13)) / AVERAGE(ParseTime(RunTime1!I13),ParseTime(RunTime2!I13),ParseTime(RunTime3!I13),ParseTime(RunTime4!I13)) -> 0.73069715 | S13: =AVERAGE(ParseTime(RunTime1!H13),ParseTime(RunTime2!H13),ParseTime(RunTime3!H13),ParseTime(RunTime4!H13)) / AVERAGE(ParseTime(RunTime1!I13),ParseTime(RunTime2!I13),ParseTime(RunTime3!I13),ParseTime(RunTime4!I13)) -> 1.2237631 | T13: =AVERAGE(ParseTime(RunTime1!G13),ParseTime(RunTime2!G13),ParseTime(RunTime3!G13),ParseTime(RunTime4!G13)) / AVERAGE(ParseTime(RunTime1!J13),ParseTime(RunTime2!J13),ParseTime(RunTime3!J13),ParseTime(RunTime4!J13)) -> 0.53112655 | U13: vcf2fasta-rust Validation Passed; vcflib Validation Passed
A14: Platinum | B14: chr7 | C14: NA12877 | D14: 235305 | E14: 2 | F14: 8s 719ms | G14: 2s 679ms | H14: 5s 500ms | I14: 3s 769ms | J14: 5s 738ms | K14: .48x | L14: 3.25x | M14: 1.58x | N14: .65x | O14: =AVERAGE(ParseTime(RunTime1!F14),ParseTime(RunTime2!F14),ParseTime(RunTime3!F14),ParseTime(RunTime4!F14)) / AVERAGE(ParseTime(RunTime1!J14),ParseTime(RunTime2!J14),ParseTime(RunTime3!J14),ParseTime(RunTime4!J14)) -> 1.6537028 | P14: =AVERAGE(ParseTime(RunTime1!F14),ParseTime(RunTime2!F14),ParseTime(RunTime3!F14),ParseTime(RunTime4!F14)) / AVERAGE(ParseTime(RunTime1!I14),ParseTime(RunTime2!I14),ParseTime(RunTime3!I14),ParseTime(RunTime4!I14)) -> 2.3493046 | Q14: =AVERAGE(ParseTime(RunTime1!H14),ParseTime(RunTime2!H14),ParseTime(RunTime3!H14),ParseTime(RunTime4!H14)) / AVERAGE(ParseTime(RunTime1!J14),ParseTime(RunTime2!J14),ParseTime(RunTime3!J14),ParseTime(RunTime4!J14)) -> 0.69582791 | R14: =AVERAGE(ParseTime(RunTime1!G14),ParseTime(RunTime2!G14),ParseTime(RunTime3!G14),ParseTime(RunTime4!G14)) / AVERAGE(ParseTime(RunTime1!I14),ParseTime(RunTime2!I14),ParseTime(RunTime3!I14),ParseTime(RunTime4!I14)) -> 0.78422866 | S14: =AVERAGE(ParseTime(RunTime1!H14),ParseTime(RunTime2!H14),ParseTime(RunTime3!H14),ParseTime(RunTime4!H14)) / AVERAGE(ParseTime(RunTime1!I14),ParseTime(RunTime2!I14),ParseTime(RunTime3!I14),ParseTime(RunTime4!I14)) -> 0.98851601 | T14: =AVERAGE(ParseTime(RunTime1!G14),ParseTime(RunTime2!G14),ParseTime(RunTime3!G14),ParseTime(RunTime4!G14)) / AVERAGE(ParseTime(RunTime1!J14),ParseTime(RunTime2!J14),ParseTime(RunTime3!J14),ParseTime(RunTime4!J14)) -> 0.55202766 | U14: vcf2fasta-rust Validation Passed; vcflib Validation Passed
A15: Platinum | B15: chr7 | C15: NA12878 | D15: 233608 | E15: 2 | F15: 7s 834ms | G15: 2s 559ms | H15: 6s 150ms | I15: 3s 703ms | J15: 5s 609ms | K15: .41x | L15: 3.06x | M15: 1.27x | N15: .66x | O15: =AVERAGE(ParseTime(RunTime1!F15),ParseTime(RunTime2!F15),ParseTime(RunTime3!F15),ParseTime(RunTime4!F15)) / AVERAGE(ParseTime(RunTime1!J15),ParseTime(RunTime2!J15),ParseTime(RunTime3!J15),ParseTime(RunTime4!J15)) -> 1.7054108 | P15: =AVERAGE(ParseTime(RunTime1!F15),ParseTime(RunTime2!F15),ParseTime(RunTime3!F15),ParseTime(RunTime4!F15)) / AVERAGE(ParseTime(RunTime1!I15),ParseTime(RunTime2!I15),ParseTime(RunTime3!I15),ParseTime(RunTime4!I15)) -> 2.0313899 | Q15: =AVERAGE(ParseTime(RunTime1!H15),ParseTime(RunTime2!H15),ParseTime(RunTime3!H15),ParseTime(RunTime4!H15)) / AVERAGE(ParseTime(RunTime1!J15),ParseTime(RunTime2!J15),ParseTime(RunTime3!J15),ParseTime(RunTime4!J15)) -> 0.93892786 | R15: =AVERAGE(ParseTime(RunTime1!G15),ParseTime(RunTime2!G15),ParseTime(RunTime3!G15),ParseTime(RunTime4!G15)) / AVERAGE(ParseTime(RunTime1!I15),ParseTime(RunTime2!I15),ParseTime(RunTime3!I15),ParseTime(RunTime4!I15)) -> 0.61257982 | S15: =AVERAGE(ParseTime(RunTime1!H15),ParseTime(RunTime2!H15),ParseTime(RunTime3!H15),ParseTime(RunTime4!H15)) / AVERAGE(ParseTime(RunTime1!I15),ParseTime(RunTime2!I15),ParseTime(RunTime3!I15),ParseTime(RunTime4!I15)) -> 1.1183983 | T15: =AVERAGE(ParseTime(RunTime1!G15),ParseTime(RunTime2!G15),ParseTime(RunTime3!G15),ParseTime(RunTime4!G15)) / AVERAGE(ParseTime(RunTime1!J15),ParseTime(RunTime2!J15),ParseTime(RunTime3!J15),ParseTime(RunTime4!J15)) -> 0.51427856 | U15: vcf2fasta-rust Validation Passed; vcflib Validation Passed
A16: Platinum | B16: chr8 | C16: NA12877 | D16: 222180 | E16: 2 | F16: 7s 534ms | G16: 2s 548ms | H16: 5s 134ms | I16: 3s 835ms | J16: 4s 950ms | K16: .49x | L16: 2.95x | M16: 1.46x | N16: .77x | O16: =AVERAGE(ParseTime(RunTime1!F16),ParseTime(RunTime2!F16),ParseTime(RunTime3!F16),ParseTime(RunTime4!F16)) / AVERAGE(ParseTime(RunTime1!J16),ParseTime(RunTime2!J16),ParseTime(RunTime3!J16),ParseTime(RunTime4!J16)) -> 1.6240389 | P16: =AVERAGE(ParseTime(RunTime1!F16),ParseTime(RunTime2!F16),ParseTime(RunTime3!F16),ParseTime(RunTime4!F16)) / AVERAGE(ParseTime(RunTime1!I16),ParseTime(RunTime2!I16),ParseTime(RunTime3!I16),ParseTime(RunTime4!I16)) -> 1.7224232 | Q16: =AVERAGE(ParseTime(RunTime1!H16),ParseTime(RunTime2!H16),ParseTime(RunTime3!H16),ParseTime(RunTime4!H16)) / AVERAGE(ParseTime(RunTime1!J16),ParseTime(RunTime2!J16),ParseTime(RunTime3!J16),ParseTime(RunTime4!J16)) -> 0.9948546 | R16: =AVERAGE(ParseTime(RunTime1!G16),ParseTime(RunTime2!G16),ParseTime(RunTime3!G16),ParseTime(RunTime4!G16)) / AVERAGE(ParseTime(RunTime1!I16),ParseTime(RunTime2!I16),ParseTime(RunTime3!I16),ParseTime(RunTime4!I16)) -> 0.80495432 | S16: =AVERAGE(ParseTime(RunTime1!H16),ParseTime(RunTime2!H16),ParseTime(RunTime3!H16),ParseTime(RunTime4!H16)) / AVERAGE(ParseTime(RunTime1!I16),ParseTime(RunTime2!I16),ParseTime(RunTime3!I16),ParseTime(RunTime4!I16)) -> 1.0551229 | T16: =AVERAGE(ParseTime(RunTime1!G16),ParseTime(RunTime2!G16),ParseTime(RunTime3!G16),ParseTime(RunTime4!G16)) / AVERAGE(ParseTime(RunTime1!J16),ParseTime(RunTime2!J16),ParseTime(RunTime3!J16),ParseTime(RunTime4!J16)) -> 0.75897554 | U16: vcf2fasta-rust Validation Passed; vcflib Validation Passed
A17: Platinum | B17: chr8 | C17: NA12878 | D17: 215330 | E17: 2 | F17: 8s 184ms | G17: 2s 355ms | H17: 4s 941ms | I17: 3s 552ms | J17: 8s 189ms | K17: .47x | L17: 3.47x | M17: 1.65x | N17: .43x | O17: =AVERAGE(ParseTime(RunTime1!F17),ParseTime(RunTime2!F17),ParseTime(RunTime3!F17),ParseTime(RunTime4!F17)) / AVERAGE(ParseTime(RunTime1!J17),ParseTime(RunTime2!J17),ParseTime(RunTime3!J17),ParseTime(RunTime4!J17)) -> 1.3993248 | P17: =AVERAGE(ParseTime(RunTime1!F17),ParseTime(RunTime2!F17),ParseTime(RunTime3!F17),ParseTime(RunTime4!F17)) / AVERAGE(ParseTime(RunTime1!I17),ParseTime(RunTime2!I17),ParseTime(RunTime3!I17),ParseTime(RunTime4!I17)) -> 1.8443183 | Q17: =AVERAGE(ParseTime(RunTime1!H17),ParseTime(RunTime2!H17),ParseTime(RunTime3!H17),ParseTime(RunTime4!H17)) / AVERAGE(ParseTime(RunTime1!J17),ParseTime(RunTime2!J17),ParseTime(RunTime3!J17),ParseTime(RunTime4!J17)) -> 0.93448158 | R17: =AVERAGE(ParseTime(RunTime1!G17),ParseTime(RunTime2!G17),ParseTime(RunTime3!G17),ParseTime(RunTime4!G17)) / AVERAGE(ParseTime(RunTime1!I17),ParseTime(RunTime2!I17),ParseTime(RunTime3!I17),ParseTime(RunTime4!I17)) -> 0.65510125 | S17: =AVERAGE(ParseTime(RunTime1!H17),ParseTime(RunTime2!H17),ParseTime(RunTime3!H17),ParseTime(RunTime4!H17)) / AVERAGE(ParseTime(RunTime1!I17),ParseTime(RunTime2!I17),ParseTime(RunTime3!I17),ParseTime(RunTime4!I17)) -> 1.2316523 | T17: =AVERAGE(ParseTime(RunTime1!G17),ParseTime(RunTime2!G17),ParseTime(RunTime3!G17),ParseTime(RunTime4!G17)) / AVERAGE(ParseTime(RunTime1!J17),ParseTime(RunTime2!J17),ParseTime(RunTime3!J17),ParseTime(RunTime4!J17)) -> 0.49703968 | U17: vcf2fasta-rust Validation Passed; vcflib Validation Passed
... A47: Platinum | B47: chrX | C47: NA12878 | D47: 127106 | E47: 2 | F47: 16s 668ms | G47: 2s 153ms | H47: 3s 62ms | I47: 4s 159ms | J47: 3s 926ms | K47: .70x | L47: 7.74x | M47: 5.44x | N47: 1.05x | O47: =AVERAGE(ParseTime(RunTime1!F47),ParseTime(RunTime2!F47),ParseTime(RunTime3!F47),ParseTime(RunTime4!F47)) / AVERAGE(ParseTime(RunTime1!J47),ParseTime(RunTime2!J47),ParseTime(RunTime3!J47),ParseTime(RunTime4!J47)) -> 4.5500195 | P47: =AVERAGE(ParseTime(RunTime1!F47),ParseTime(RunTime2!F47),ParseTime(RunTime3!F47),ParseTime(RunTime4!F47)) / AVERAGE(ParseTime(RunTime1!I47),ParseTime(RunTime2!I47),ParseTime(RunTime3!I47),ParseTime(RunTime4!I47)) -> 4.2722171 | Q47: =AVERAGE(ParseTime(RunTime1!H47),ParseTime(RunTime2!H47),ParseTime(RunTime3!H47),ParseTime(RunTime4!H47)) / AVERAGE(ParseTime(RunTime1!J47),ParseTime(RunTime2!J47),ParseTime(RunTime3!J47),ParseTime(RunTime4!J47)) -> 1.2289204 | R47: =AVERAGE(ParseTime(RunTime1!G47),ParseTime(RunTime2!G47),ParseTime(RunTime3!G47),ParseTime(RunTime4!G47)) / AVERAGE(ParseTime(RunTime1!I47),ParseTime(RunTime2!I47),ParseTime(RunTime3!I47),ParseTime(RunTime4!I47)) -> 0.56078073 | S47: =AVERAGE(ParseTime(RunTime1!H47),ParseTime(RunTime2!H47),ParseTime(RunTime3!H47),ParseTime(RunTime4!H47)) / AVERAGE(ParseTime(RunTime1!I47),ParseTime(RunTime2!I47),ParseTime(RunTime3!I47),ParseTime(RunTime4!I47)) -> 1.1538884 | T47: =AVERAGE(ParseTime(RunTime1!G47),ParseTime(RunTime2!G47),ParseTime(RunTime3!G47),ParseTime(RunTime4!G47)) / AVERAGE(ParseTime(RunTime1!J47),ParseTime(RunTime2!J47),ParseTime(RunTime3!J47),ParseTime(RunTime4!J47)) -> 0.59724568 | U47: vcf2fasta-rust Validation Passed; vcflib Validation Passed

Sheet RunTime3
A1: Dataset | B1: Chromosome | C1: Sample | D1: Variants | E1: Ploidy | F1: vcflib | G1: cpu_t1_time | H1: cpu_t2_time | I1: gpu_t1_time | J1: gpu_t2_time | K1: speedup_cpu_t2_vs_t1 | L1: speedup_cpu_t1_vs_vcflib | M1: speedup_cpu_t2_vs_vcflib | N1: speedup_gpu_t2_vs_t1 | O1: speedup_gpu_t2_vs_vcflib | P1: speedup_gpu_t1_vs_vcflib | Q1: speedup_gpu_t2_vs_cpu_t2 | R1: speedup_gpu_t1_vs_cpu_t1 | S1: speedup_gpu_t1_vs_cpu_t2 | T1: speedup_gpu_t2_vs_cpu_t1 | U1: Notes
A2: Platinum | B2: chr1 | C2: NA12877 | D2: 319247 | E2: 2 | F2: 12m 21s 93ms | G2: 7s 945ms | H2: 6s 147ms | I2: 5s 262ms | J2: 6s 583ms | K2: 1.29x | L2: 93.28x | M2: 120.55x | N2: .79x | O2: =AVERAGE(ParseTime(RunTime1!F2),ParseTime(RunTime2!F2),ParseTime(RunTime3!F2),ParseTime(RunTime4!F2)) / AVERAGE(ParseTime(RunTime1!J2),ParseTime(RunTime2!J2),ParseTime(RunTime3!J2),ParseTime(RunTime4!J2)) -> 140.80047 | P2: =AVERAGE(ParseTime(RunTime1!F2),ParseTime(RunTime2!F2),ParseTime(RunTime3!F2),ParseTime(RunTime4!F2)) / AVERAGE(ParseTime(RunTime1!I2),ParseTime(RunTime2!I2),ParseTime(RunTime3!I2),ParseTime(RunTime4!I2)) -> 150.16231 | Q2: =AVERAGE(ParseTime(RunTime1!H2),ParseTime(RunTime2!H2),ParseTime(RunTime3!H2),ParseTime(RunTime4!H2)) / AVERAGE(ParseTime(RunTime1!J2),ParseTime(RunTime2!J2),ParseTime(RunTime3!J2),ParseTime(RunTime4!J2)) -> 1.0387539 | R2: =AVERAGE(ParseTime(RunTime1!G2),ParseTime(RunTime2!G2),ParseTime(RunTime3!G2),ParseTime(RunTime4!G2)) / AVERAGE(ParseTime(RunTime1!I2),ParseTime(RunTime2!I2),ParseTime(RunTime3!I2),ParseTime(RunTime4!I2)) -> 1.0428153 | S2: =AVERAGE(ParseTime(RunTime1!H2),ParseTime(RunTime2!H2),ParseTime(RunTime3!H2),ParseTime(RunTime4!H2)) / AVERAGE(ParseTime(RunTime1!I2),ParseTime(RunTime2!I2),ParseTime(RunTime3!I2),ParseTime(RunTime4!I2)) -> 1.1078207 | T2: =AVERAGE(ParseTime(RunTime1!G2),ParseTime(RunTime2!G2),ParseTime(RunTime3!G2),ParseTime(RunTime4!G2)) / AVERAGE(ParseTime(RunTime1!J2),ParseTime(RunTime2!J2),ParseTime(RunTime3!J2),ParseTime(RunTime4!J2)) -> 0.97780119 | U2: vcf2fasta-rust Validation Passed; vcflib Validation Passed
A3: Platinum | B3: chr1 | C3: NA12878 | D3: 316061 | E3: 2 | F3: 12m 36s 583ms | G3: 5s 261ms | H3: 5s 902ms | I3: 6s 455ms | J3: 6s 41ms | K3: .89x | L3: 143.81x | M3: 128.19x | N3: 1.06x | O3: =AVERAGE(ParseTime(RunTime1!F3),ParseTime(RunTime2!F3),ParseTime(RunTime3!F3),ParseTime(RunTime4!F3)) / AVERAGE(ParseTime(RunTime1!J3),ParseTime(RunTime2!J3),ParseTime(RunTime3!J3),ParseTime(RunTime4!J3)) -> 121.73841 | P3: =AVERAGE(ParseTime(RunTime1!F3),ParseTime(RunTime2!F3),ParseTime(RunTime3!F3),ParseTime(RunTime4!F3)) / AVERAGE(ParseTime(RunTime1!I3),ParseTime(RunTime2!I3),ParseTime(RunTime3!I3),ParseTime(RunTime4!I3)) -> 131.53884 | Q3: =AVERAGE(ParseTime(RunTime1!H3),ParseTime(RunTime2!H3),ParseTime(RunTime3!H3),ParseTime(RunTime4!H3)) / AVERAGE(ParseTime(RunTime1!J3),ParseTime(RunTime2!J3),ParseTime(RunTime3!J3),ParseTime(RunTime4!J3)) -> 0.94838583 | R3: =AVERAGE(ParseTime(RunTime1!G3),ParseTime(RunTime2!G3),ParseTime(RunTime3!G3),ParseTime(RunTime4!G3)) / AVERAGE(ParseTime(RunTime1!I3),ParseTime(RunTime2!I3),ParseTime(RunTime3!I3),ParseTime(RunTime4!I3)) -> 1.1331022 | S3: =AVERAGE(ParseTime(RunTime1!H3),ParseTime(RunTime2!H3),ParseTime(RunTime3!H3),ParseTime(RunTime4!H3)) / AVERAGE(ParseTime(RunTime1!I3),ParseTime(RunTime2!I3),ParseTime(RunTime3!I3),ParseTime(RunTime4!I3)) -> 1.0247347 | T3: =AVERAGE(ParseTime(RunTime1!G3),ParseTime(RunTime2!G3),ParseTime(RunTime3!G3),ParseTime(RunTime4!G3)) / AVERAGE(ParseTime(RunTime1!J3),ParseTime(RunTime2!J3),ParseTime(RunTime3!J3),ParseTime(RunTime4!J3)) -> 1.0486793 | U3: vcf2fasta-rust Validation Passed; vcflib Validation Passed
